Workbook

Sheet CorST
A1: Слово | B1: Частота-CorST | C1: IPM-CorST | D1: Ранг-CorST | E1: Номер строки, на которой слово стоит в RLC | F1: IPM-RLC
A2: в | B2: 35889 | C2: 11520.564 | E2: =MATCH(A2, RLC!A:A, 0) -> 3 | F2: {=INDEX(RLC!B:B, E2)} -> 28595
A3: и | B3: 31435 | C3: 10090.806 | E3: =MATCH(A3, RLC!A:A, 0) -> 2 | F3: {=INDEX(RLC!B:B, E3)} -> 28852
A4: на | B4: 13212 | C4: 4241.1239 | E4: =MATCH(A4, RLC!A:A, 0) -> 5 | F4: {=INDEX(RLC!B:B, E4)} -> 9984
A5: не | B5: 11811 | C5: 3791.3953 | E5: =MATCH(A5, RLC!A:A, 0) -> 6 | F5: {=INDEX(RLC!B:B, E5)} -> 9679
A6: с | B6: 11363 | C6: 3647.5848 | E6: =MATCH(A6, RLC!A:A, 0) -> 8 | F6: {=INDEX(RLC!B:B, E6)} -> 6908
A7: что | B7: 10265 | C7: 3295.1208 | E7: =MATCH(A7, RLC!A:A, 0) -> 4 | F7: {=INDEX(RLC!B:B, E7)} -> 12272
A8: как | B8: 7396 | C8: 2374.1562 | E8: =MATCH(A8, RLC!A:A, 0) -> 9 | F8: {=INDEX(RLC!B:B, E8)} -> 6227
A9: к | B9: 6790 | C9: 2179.6269 | E9: =MATCH(A9, RLC!A:A, 0) -> 15 | F9: {=INDEX(RLC!B:B, E9)} -> 3569
A10: а | B10: 5924 | C10: 1901.6362 | E10: =MATCH(A10, RLC!A:A, 0) -> 20 | F10: {=INDEX(RLC!B:B, E10)} -> 2596
A11: для | B11: 5652 | C11: 1814.3227 | E11: =MATCH(A11, RLC!A:A, 0) -> 14 | F11: {=INDEX(RLC!B:B, E11)} -> 3770
A12: по | B12: 5634 | C12: 1808.5447 | E12: =MATCH(A12, RLC!A:A, 0) -> 16 | F12: {=INDEX(RLC!B:B, E12)} -> 3493
A13: о | B13: 4912 | C13: 1576.7787 | E13: =MATCH(A13, RLC!A:A, 0) -> 13 | F13: {=INDEX(RLC!B:B, E13)} -> 3780
... A1349: форм | B1349: 92 | C1349: 29.532501 | E1349: =MATCH(A1349, RLC!A:A, 0) -> 5289 | F1349: {=INDEX(RLC!B:B, E1349)} -> 16
A1350: школе | B1350: 92 | C1350: 29.532501 | E1350: =MATCH(A1350, RLC!A:A, 0) -> 404 | F1350: {=INDEX(RLC!B:B, E1350)} -> 195 | G1350: =C1350>E1350 -> FALSE
A1351: элементов | B1351: 92 | C1351: 29.532501 | E1351: =MATCH(A1351, RLC!A:A, 0) -> 4112 | F1351: {=INDEX(RLC!B:B, E1351)} -> 21
A1352: этими | B1352: 92 | C1352: 29.532501 | E1352: =MATCH(A1352, RLC!A:A, 0) -> 1492 | F1352: {=INDEX(RLC!B:B, E1352)} -> 58
A1353: артикля | B1353: 91 | C1353: 29.211495 | E1353: =MATCH(A1353, RLC!A:A, 0) -> #N/A | F1353: {=INDEX(RLC!B:B, E1353)} -> #N/A
A1354: всему | B1354: 91 | C1354: 29.211495 | E1354: =MATCH(A1354, RLC!A:A, 0) -> 741 | F1354: {=INDEX(RLC!B:B, E1354)} -> 109
A1355: выполнения | B1355: 91 | C1355: 29.211495 | E1355: =MATCH(A1355, RLC!A:A, 0) -> #N/A | F1355: {=INDEX(RLC!B:B, E1355)} -> #N/A
A1356: достоевский | B1356: 91 | C1356: 29.211495 | E1356: =MATCH(A1356, RLC!A:A, 0) -> #N/A | F1356: {=INDEX(RLC!B:B, E1356)} -> #N/A
A1357: менеджмента | B1357: 91 | C1357: 29.211495 | E1357: =MATCH(A1357, RLC!A:A, 0) -> 2858 | F1357: {=INDEX(RLC!B:B, E1357)} -> 30
A1358: наша | B1358: 91 | C1358: 29.211495 | E1358: =MATCH(A1358, RLC!A:A, 0) -> 551 | F1358: {=INDEX(RLC!B:B, E1358)} -> 146
A1359: поднятая | B1359: 91 | C1359: 29.211495 | E1359: =MATCH(A1359, RLC!A:A, 0) -> #N/A | F1359: {=INDEX(RLC!B:B, E1359)} -> #N/A
A1360: постепенно | B1360: 91 | C1360: 29.211495 | E1360: =MATCH(A1360, RLC!A:A, 0) -> 2469 | F1360: {=INDEX(RLC!B:B, E1360)} -> 35
A1361: рублей | B1361: 91 | C1361: 29.211495 | E1361: =MATCH(A1361, RLC!A:A, 0) -> 1697 | F1361: {=INDEX(RLC!B:B, E1361)} -> 51
A1362: сегодняшний | B1362: 91 | C1362: 29.211495 | E1362: =MATCH(A1362, RLC!A:A, 0) -> 1873 | F1362: {=INDEX(RLC!B:B, E1362)} -> 47
... A1716: чехов | B1716: 73 | C1716: 23.433397 | E1716: =MATCH(A1716, RLC!A:A, 0) -> #N/A | F1716: {=INDEX(RLC!B:B, E1716)} -> #N/A
A1717: шапочка | B1717: 73 | C1717: 23.433397 | E1717: =MATCH(A1717, RLC!A:A, 0) -> 3340 | F1717: {=INDEX(RLC!B:B, E1717)} -> 26 | G1717: =C1717>E1717 -> FALSE
A1718: широко | B1718: 73 | C1718: 23.433397 | E1718: =MATCH(A1718, RLC!A:A, 0) -> 1585 | F1718: {=INDEX(RLC!B:B, E1718)} -> 55 | G1718: =C1718>E1718 -> FALSE
A1719: эмоций | B1719: 73 | C1719: 23.433397 | E1719: =MATCH(A1719, RLC!A:A, 0) -> 6913 | F1719: {=INDEX(RLC!B:B, E1719)} -> 12
A1720: большие | B1720: 72 | C1720: 23.112392 | E1720: =MATCH(A1720, RLC!A:A, 0) -> 837 | F1720: {=INDEX(RLC!B:B, E1720)} -> 97
A1721: большого | B1721: 72 | C1721: 23.112392 | E1721: =MATCH(A1721, RLC!A:A, 0) -> 2651 | F1721: {=INDEX(RLC!B:B, E1721)} -> 32
A1722: ведет | B1722: 72 | C1722: 23.112392 | E1722: =MATCH(A1722, RLC!A:A, 0) -> 3483 | F1722: {=INDEX(RLC!B:B, E1722)} -> 24
A1723: вниз | B1723: 72 | C1723: 23.112392 | E1723: =MATCH(A1723, RLC!A:A, 0) -> 2832 | F1723: {=INDEX(RLC!B:B, E1723)} -> 30
A1724: вузов | B1724: 72 | C1724: 23.112392 | E1724: =MATCH(A1724, RLC!A:A, 0) -> 6052 | F1724: {=INDEX(RLC!B:B, E1724)} -> 13
A1725: выражений | B1725: 72 | C1725: 23.112392 | E1725: =MATCH(A1725, RLC!A:A, 0) -> 3786 | F1725: {=INDEX(RLC!B:B, E1725)} -> 22
A1726: гражданским | B1726: 72 | C1726: 23.112392 | E1726: =MATCH(A1726, RLC!A:A, 0) -> #N/A | F1726: {=INDEX(RLC!B:B, E1726)} -> #N/A
A1727: изучить | B1727: 72 | C1727: 23.112392 | E1727: =MATCH(A1727, RLC!A:A, 0) -> 4372 | F1727: {=INDEX(RLC!B:B, E1727)} -> 19
A1728: ин | B1728: 72 | C1728: 23.112392 | E1728: =MATCH(A1728, RLC!A:A, 0) -> #N/A | F1728: {=INDEX(RLC!B:B, E1728)} -> #N/A
...

Sheet RLC
A1: Слово | B1: Частота-RLC | C1: IPM-RLC | D1: Ранг-RLC | E1: Номер строки, на которой слово стоит в CorST
A2: и | B2: 28852 | C2: 38334.702 | E2: =MATCH(A2, CorST!A:A, 0) -> 3
A3: в | B3: 28595 | C3: 37993.234 | E3: =MATCH(A3, CorST!A:A, 0) -> 2
A4: что | B4: 12272 | C4: 16305.402 | E4: =MATCH(A4, CorST!A:A, 0) -> 7
A5: на | B5: 9984 | C5: 13265.412 | E5: =MATCH(A5, CorST!A:A, 0) -> 4
A6: не | B6: 9679 | C6: 12860.168 | E6: =MATCH(A6, CorST!A:A, 0) -> 5
A7: я | B7: 8489 | C7: 11279.055 | E7: =MATCH(A7, CorST!A:A, 0) -> 24
A8: с | B8: 6908 | C8: 9178.432 | E8: =MATCH(A8, CorST!A:A, 0) -> 6
A9: как | B9: 6227 | C9: 8273.6097 | E9: =MATCH(A9, CorST!A:A, 0) -> 8
A10: это | B10: 5389 | C10: 7160.1868 | E10: =MATCH(A10, CorST!A:A, 0) -> 15
A11: но | B11: 4307 | C11: 5722.569 | E11: =MATCH(A11, CorST!A:A, 0) -> 19
A12: он | B12: 4050 | C12: 5381.1016 | E12: =MATCH(A12, CorST!A:A, 0) -> 21
A13: о | B13: 3780 | C13: 5022.3615 | E13: =MATCH(A13, CorST!A:A, 0) -> 13
... A8127: японский | B8127: 10 | C8127: 13.286671 | E8127: =MATCH(A8127, CorST!A:A, 0) -> 14067

Sheet merge
A1: Слово | B1: IPM-CorST | C1: IPM-RLC | D1: Разница CorST - RLC
A2: а | B2: 1901.6362 | C2: 2596
A3: предлога | B3: 347.9699
A4: абзац | B4: 86.029458 | C4: 57
A5: предлогов | B5: 215.07365
A6: абзаце | B6: 43.014729 | C6: 18
A7: ст | B7: 188.7512
A8: значений | B8: 185.86215
A9: предлог | B9: 132.57525
A10: абитуриентов | B10: 3.2100544 | C10: 21
A11: напишите | C11: 182
A12: сети | B12: 106.2528
A13: абсолютно | B13: 35.631604 | C13: 61
A14: фрагмент | B14: 99.190681
A15: восприятия | B15: 94.375599
A16: судьи | B16: 92.770572
A17: судей | B17: 89.239512
A18: делу | B18: 88.918507
A19: абстрактные | B19: 8.6671469 | C19: 11
A20: колобок | B20: 80.25136
A21: ред | B21: 79.288344
A22: выделить | B22: 76.078289
A23: глагола | B23: 74.473262
A24: объекта | B24: 73.831251
A25: абсурда | B25: 9.3091578 | C25: 10
A26: озеро | C26: 173
A27: антибиотиков | C27: 156
A28: американцев | C28: 153
A29: байкал | C29: 150
A30: войне | C30: 146
A31: геополитика | C31: 134
A32: электронный | B32: 69.658181
A33: августа | B33: 25.680435 | C33: 43
A34: американцы | C34: 132
A35: синонимов | B35: 69.337175
A36: психологии | B36: 66.769132
A37: рабству | B37: 66.769132
A38: линднер | B38: 65.806115
A39: автобус | B39: 3.8520653 | C39: 11
A40: маяковского | C40: 131
...
